Workbook

Sheet Shrawan
A1: NEPAL ELECTRICITY AUTHORITY
A2: DHARAN DISTRIBUTION CENTER
A4: Peak Load Details
A6: Month: | B6: Shrawan | C6: 2082
A8: Day | B8: 33KV Duhabi-Dharan | F8: 33KV Dharan-Dhankuta | J8: 33KV Dharan-Chatara Bayarban | N8: 33/11KV, 16.6MVA Power Trf 1 | P8: 11KV Incomer 1 | R8: Dharan | T8: Bagarkot | V8: Local Chatara | X8: BPKIHS | Z8: 33/11KV, 8MVA Power Trf 2 | AB8: 11KV Incomer 2 | AD8: Khanepani | AF8: Railway | AH8: British | AJ8: Industrial | AL8: 33/11KV, 8MVA Power Trf 3 | AN8: 11KV Incomer 3 | AP8: Bhanu | AR8: Panmara
B9: Max. Import (A) | C9: Time | D9: Max. Export (A) | E9: Time | F9: Max. Import (A) | G9: Time | H9: Max. Export (A) | I9: Time | J9: Max. Import (A) | K9: Time | L9: Max. Export (A) | M9: Time | N9: Max. (A) | O9: Time | P9: Max. (A) | Q9: Time | R9: Max. (A) | S9: Time | T9: Max. (A) | U9: Time | V9: Max. (A) | W9: Time | X9: Max. (A) | Y9: Time | Z9: Max. (A) | AA9: Time | AB9: Max. (A) | AC9: Time | AD9: Max. (A) | AE9: Time | AF9: Max. (A) | AG9: Time | AH9: Max. (A) | AI9: Time | AJ9: Max. (A) | AK9: Time | AL9: Max. (A) | AM9: Time | AN9: Max. (A) | AO9: Time | AP9: Max. (A) | AQ9: Time | AR9: Max. (A) | AS9: Time
A10: 1 | B10: 388 | C10: 0.8125 | H10: 45 | I10: 0.29166667 | L10: 1.2 | M10: 0.8125 | N10: 206 | O10: 0.8125 | P10: 569 | Q10: 0.8125 | R10: 172 | S10: 0.8125 | T10: 156 | U10: 0.8125 | V10: 250 | W10: 0.8125 | X10: 41 | Y10: 0.41666667 | Z10: 60 | AA10: 0.875 | AB10: 171 | AC10: 0.875 | AD10: 53 | AE10: 0.5 | AF10: 75 | AG10: 0.83333333 | AH10: 34 | AI10: 0.875 | AJ10: 42 | AK10: 0.41666667 | AL10: 83 | AM10: 0.8125 | AN10: 250 | AO10: 0.8125 | AP10: 166 | AQ10: 0.8125 | AR10: 68 | AS10: 0.83333333
A11: 2 | B11: 418 | C11: 0.83333333 | H11: 21 | I11: 0.8125 | L11: 1.7 | M11: 0.5 | N11: 208 | O11: 0.83333333 | P11: 579 | Q11: 0.83333333 | R11: 182 | S11: 0.8125 | T11: 157 | U11: 0.83333333 | V11: 247 | W11: 0.83333333 | X11: 41 | Y11: 0.375 | Z11: 79 | AA11: 0.83333333 | AB11: 215 | AC11: 0.83333333 | AD11: 54 | AE11: 0.66666667 | AF11: 128 | AG11: 0.83333333 | AH11: 35 | AI11: 0.875 | AJ11: 54 | AK11: 0.33333333 | AL11: 86 | AM11: 0.83333333 | AN11: 239 | AO11: 0.83333333 | AP11: 181 | AQ11: 0.45833333 | AR11: 70 | AS11: 19;30
A12: 3 | B12: 410 | C12: 0.8125 | H12: 21 | I12: 0.8125 | L12: 1.2 | M12: 0.77083333 | N12: 223 | O12: 0.8125 | P12: 620 | Q12: 0.8125 | R12: 191 | S12: 0.8125 | T12: 157 | U12: 0.8125 | V12: 259 | W12: 0.8125 | X12: 24 | Y12: 0.5 | Z12: 61 | AA12: 0.8125 | AB12: 172 | AC12: 0.8125 | AD12: 51 | AE12: 0.58333333 | AF12: 76 | AG12: 0.8125 | AH12: 37 | AI12: 0.8125 | AJ12: 15 | AK12: 0.375 | AL12: 85 | AM12: 0.79166667 | AN12: 246 | AO12: 0.79166667 | AP12: 178 | AQ12: 0.79166667 | AR12: 67 | AS12: 0.79166667
A13: 4 | B13: 360 | C13: 0.83333333 | H13: 18 | I13: 0.8125 | L13: 1.2 | M13: 0.77083333 | N13: 190 | O13: 0.8125 | P13: 532 | Q13: 0.8125 | R13: 157 | S13: 0.8125 | T13: 141 | U13: 0.83333333 | V13: 222 | W13: 0.8125 | X13: 39 | Y13: 0.83333333 | Z13: 56 | AA13: 0.83333333 | AB13: 163 | AC13: 0.83333333 | AD13: 48 | AE13: 0.25 | AF13: 70 | AG13: 0.875 | AH13: 33 | AI13: 0.875 | AJ13: 45 | AK13: 0.45833333 | AL13: 72 | AM13: 0.8125 | AN13: 209 | AO13: 0.79166667 | AP13: 150 | AQ13: 0.79166667 | AR13: 61 | AS13: 0.8125
A14: 5 | B14: 406 | C14: 0.8125 | H14: 18 | I14: 0.8125 | L14: 1.3 | M14: 0.8125 | N14: 213 | O14: 0.8125 | P14: 591 | Q14: 0.8125 | R14: 180 | S14: 0.8125 | T14: 159 | U14: 0.8125 | V14: 251 | W14: 0.8125 | X14: 39 | Y14: 0.45833333 | Z14: 66 | AA14: 0.66666667 | AB14: 187 | AC14: 0.66666667 | AD14: 51 | AE14: 0.8125 | AF14: 75 | AG14: 0.83333333 | AH14: 36 | AI14: 0.83333333 | AJ14: 48 | AK14: 0.375 | AL14: 86 | AM14: 0.8125 | AN14: 242 | AO14: 0.8125 | AP14: 171 | AQ14: 0.8125 | AR14: 72 | AS14: 20;00
A15: 6 | B15: 400 | C15: 0.8125 | H15: 20 | I15: 0.8125 | L15: 6 | M15: 0.33333333 | N15: 207 | O15: 0.8125 | P15: 571 | Q15: 0.8125 | R15: 182 | S15: 0.8125 | T15: 156 | U15: 0.83333333 | V15: 251 | W15: 0.8125 | X15: 45 | Y15: 0.375 | Z15: 71 | AA15: 0.8125 | AB15: 201 | AC15: 0.8125 | AD15: 51 | AE15: 0.20833333 | AF15: 74 | AG15: 0.8125 | AH15: 67 | AI15: 0.66666667 | AJ15: 46 | AK15: 0.66666667 | AL15: 85 | AM15: 0.8125 | AN15: 237 | AO15: 0.8125 | AP15: 165 | AQ15: 0.79166667 | AR15: 71 | AS15: 0.8125
A16: 7 | B16: 425 | C16: 0.8125 | H16: 18 | I16: 0.8125 | L16: 1.3 | M16: 0.8125 | N16: 227 | O16: 0.8125 | P16: 626 | Q16: 0.8125 | R16: 192 | S16: 0.8125 | T16: 169 | U16: 0.83333333 | V16: 267 | W16: 0.8125 | X16: 39 | Y16: 0.5 | Z16: 69 | AA16: 0.33333333 | AB16: 192 | AC16: 0.33333333 | AD16: 55 | AE16: 0.8125 | AF16: 76 | AG16: 0.79166667 | AH16: 71 | AI16: 0.375 | AJ16: 38 | AK16: 0.375 | AL16: 88 | AM16: 0.8125 | AN16: 263 | AO16: 0.79166667 | AP16: 188 | AQ16: 0.79166667 | AR16: 78 | AS16: 0.8125
A17: 8 | B17: 444 | C17: 0.83333333 | H17: 20 | I17: 0.8125 | L17: 1.4 | M17: 0.77083333 | N17: 239 | O17: 0.8125 | P17: 637 | Q17: 0.8125 | R17: 195 | S17: 0.79166667 | T17: 175 | U17: 0.83333333 | V17: 274 | W17: 0.8125 | X17: 45 | Y17: 0.41666667 | Z17: 67 | AA17: 0.83333333 | AB17: 187 | AC17: 0.83333333 | AD17: 50 | AE17: 0.25 | AF17: 80 | AG17: 0.83333333 | AH17: 42 | AI17: 0.875 | AJ17: 45 | AK17: 0.45833333 | AL17: 98 | AM17: 0.79166667 | AN17: 267 | AO17: 0.79166667 | AP17: 192 | AQ17: 0.79166667 | AR17: 74 | AS17: 0.79166667
A18: 9 | B18: 406 | C18: 0.83333333 | H18: 20 | I18: 0.79166667 | J18: 16 | K18: 0.58333333 | L18: 6.1 | M18: 0.54166667 | N18: 219 | O18: 0.8125 | P18: 614 | Q18: 0.8125 | R18: 187 | S18: 0.8125 | T18: 163 | U18: 0.8125 | V18: 263 | W18: 0.8125 | X18: 43 | Y18: 0.41666667 | Z18: 65 | AA18: 0.83333333 | AB18: 184 | AC18: 0.83333333 | AD18: 50 | AE18: 0.8125 | AF18: 79 | AG18: 0.83333333 | AH18: 36 | AI18: 0.83333333 | AJ18: 55 | AK18: 0.45833333 | AL18: 90 | AM18: 0.8125 | AN18: 260 | AO18: 0.8125 | AP18: 187 | AQ18: 0.8125 | AR18: 71 | AS18: 0.8125
A19: 10 | B19: 373 | C19: 0.8125 | H19: 20 | I19: 0.8125 | J19: 14.9 | K19: 0.91666667 | N19: 208 | O19: 0.83333333 | P19: 566 | Q19: 0.83333333 | R19: 175 | S19: 0.8125 | T19: 159 | U19: 0.875 | V19: 246 | W19: 0.875 | X19: 21 | Y19: 0.41666667 | Z19: 54 | AA19: 0.45833333 | AB19: 153 | AC19: 0.45833333 | AD19: 50 | AE19: 0.16666667 | AF19: 73 | AG19: 0.875 | AH19: 36 | AI19: 0.83333333 | AJ19: 21 | AK19: 0.375 | AL19: 86 | AM19: 0.875 | AN19: 227 | AO19: 0.875 | AP19: 164 | AQ19: 0.875 | AR19: 65 | AS19: 0.8125
A20: 11 | B20: 367 | C20: 0.8125 | H20: 16 | I20: 0.875 | J20: 13.5 | K20: 0.375 | N20: 203 | O20: 0.8125 | P20: 561 | Q20: 0.8125 | R20: 175 | S20: 0.79166667 | T20: 153 | U20: 0.83333333 | V20: 238 | W20: 0.8125 | X20: 43 | Y20: 0.41666667 | Z20: 68 | AA20: 0.8125 | AB20: 177 | AC20: 0.8125 | AD20: 50 | AE20: 0.875 | AF20: 69 | AG20: 0.83333333 | AH20: 38 | AI20: 0.875 | AJ20: 56 | AK20: 0.58333333 | AL20: 83 | AM20: 0.8125 | AN20: 234 | AO20: 0.8125 | AP20: 185 | AQ20: 0.58333333 | AR20: 65 | AS20: 0.8125
A21: 12 | B21: 371 | C21: 0.8125 | H21: 20 | I21: 0.8125 | J21: 12.6 | K21: 0.33333333 | N21: 200 | O21: 0.8125 | P21: 557 | Q21: 0.8125 | R21: 167 | S21: 0.8125 | T21: 149 | U21: 0.8125 | V21: 237 | W21: 0.8125 | X21: 42 | Y21: 0.41666667 | Z21: 68 | AA21: 0.8125 | AB21: 179 | AC21: 0.8125 | AD21: 52 | AE21: 0.33333333 | AF21: 73 | AG21: 0.8125 | AH21: 34 | AI21: 0.875 | AJ21: 52 | AK21: 0.66666667 | AL21: 77 | AM21: 0.8125 | AN21: 219 | AO21: 0.8125 | AP21: 157 | AQ21: 0.8125 | AR21: 62 | AS21: 0.8125
A22: 13 | B22: 396 | C22: 0.8125 | H22: 19 | I22: 0.875 | J22: 13.6 | K22: 0.70833333 | N22: 215 | O22: 0.8125 | P22: 604 | Q22: 0.8125 | R22: 183 | S22: 0.8125 | T22: 163 | U22: 0.83333333 | V22: 257 | W22: 0.8125 | X22: 42 | Y22: 0.375 | Z22: 67 | AA22: 0.8125 | AB22: 185 | AC22: 0.8125 | AD22: 50 | AE22: 0.54166667 | AF22: 77 | AG22: 0.8125 | AH22: 37 | AI22: 0.875 | AJ22: 55 | AK22: 0.41666667 | AL22: 84 | AM22: 0.8125 | AN22: 238 | AO22: 0.8125 | AP22: 169 | AQ22: 0.8125 | AR22: 68 | AS22: 0.8125
A23: 14 | B23: 380 | C23: 0.8125 | H23: 19 | I23: 0.8125 | J23: 20.4 | K23: 0.91666667 | N23: 206 | O23: 0.8125 | P23: 571 | Q23: 0.8125 | R23: 180 | S23: 0.8125 | T23: 157 | U23: 0.875 | V23: 238 | W23: 0.83333333 | X23: 43 | Y23: 0.41666667 | Z23: 64 | AA23: 0.875 | AB23: 178 | AC23: 0.875 | AD23: 51 | AE23: 0.875 | AF23: 74 | AG23: 0.83333333 | AH23: 49 | AI23: 0.83333333 | AJ23: 49 | AK23: 0.41666667 | AL23: 84 | AM23: 0.79166667 | AN23: 231 | AO23: 0.79166667 | AP23: 167 | AQ23: 0.79166667 | AR23: 66 | AS23: 0.8125
A24: 15 | B24: 390 | C24: 0.8125 | H24: 19 | I24: 0.8125 | J24: 15.8 | K24: 0.33333333 | N24: 212 | O24: 0.8125 | P24: 586 | Q24: 0.8125 | R24: 179 | S24: 0.8125 | T24: 158 | U24: 0.875 | V24: 249 | W24: 0.8125 | X24: 43 | Y24: 0.41666667 | Z24: 64 | AA24: 0.8125 | AB24: 180 | AC24: 0.8125 | AD24: 50 | AE24: 0.33333333 | AF24: 69 | AG24: 0.875 | AH24: 37 | AI24: 0.83333333 | AJ24: 54 | AK24: 0.41666667 | AL24: 84 | AM24: 0.8125 | AN24: 226 | AO24: 0.8125 | AP24: 168 | AQ24: 0.8125 | AR24: 68 | AS24: 0.875
A25: 16 | B25: 354 | C25: 0.8125 | H25: 19 | I25: 0.8125 | J25: 14.6 | K25: 0.77083333 | N25: 197 | O25: 0.8125 | P25: 556 | Q25: 0.8125 | R25: 176 | S25: 0.79166667 | T25: 152 | U25: 0.83333333 | V25: 236 | W25: 0.83333333 | X25: 43 | Y25: 0.375 | Z25: 59 | AA25: 0.33333333 | AB25: 170 | AC25: 0.33333333 | AD25: 52 | AE25: 0.33333333 | AF25: 69 | AG25: 0.83333333 | AH25: 33 | AI25: 0.875 | AJ25: 41 | AK25: 0.45833333 | AL25: 79 | AM25: 0.79166667 | AN25: 226 | AO25: 0.79166667 | AP25: 162 | AQ25: 0.79166667 | AR25: 66 | AS25: 0.83333333
A26: 17 | B26: 352 | C26: 0.8125 | H26: 18 | I26: 0.8125 | J26: 18.4 | K26: 0.33333333 | N26: 208 | O26: 0.8125 | P26: 590 | Q26: 0.8125 | R26: 174 | S26: 0.8125 | T26: 156 | U26: 0.83333333 | V26: 238 | W26: 0.8125 | X26: 22 | Y26: 0.45833333 | Z26: 48 | AA26: 0.8125 | AB26: 141 | AC26: 0.8125 | AD26: 48 | AE26: 0.25 | AF26: 71 | AG26: 0.8125 | AH26: 31 | AI26: 0.91666667 | AJ26: 13 | AK26: 0.45833333 | AL26: 79 | AM26: 0.8125 | AN26: 226 | AO26: 0.8125 | AP26: 156 | AQ26: 0.8125 | AR26: 66 | AS26: 0.8125
A27: 18 | B27: 369 | C27: 0.8125 | H27: 34 | I27: 0.5 | J27: 15 | K27: 0.79166667 | N27: 196 | O27: 0.8125 | P27: 521 | Q27: 0.8125 | R27: 158 | S27: 0.8125 | T27: 139 | U27: 0.8125 | V27: 220 | W27: 0.8125 | X27: 41 | Y27: 0.33333333 | Z27: 59 | AA27: 0.54166667 | AB27: 172 | AC27: 0.54166667 | AD27: 53 | AE27: 0.54166667 | AF27: 66 | AG27: 0.83333333 | AH27: 29 | AI27: 0.29166667 | AJ27: 60 | AK27: 0.45833333 | AL27: 76 | AM27: 0.79166667 | AN27: 208 | AO27: 0.79166667 | AP27: 167 | AQ27: 0.41666667 | AR27: 58 | AS27: 0.8125
A28: 19 | B28: 338 | C28: 0.8125 | H28: 17 | I28: 0.8125 | J28: 15 | K28: 0.375 | N28: 189 | O28: 0.8125 | P28: 524 | Q28: 0.8125 | R28: 157 | S28: 0.8125 | T28: 146 | U28: 0.875 | V28: 224 | W28: 0.83333333 | X28: 42 | Y28: 0.45833333 | Z28: 54 | AA28: 0.8125 | AB28: 143 | AC28: 0.8125 | AD28: 49 | AE28: 0.20833333 | AF28: 68 | AG28: 0.8125 | AH28: 31 | AI28: 0.875 | AJ28: 47 | AK28: 0.375 | AL28: 78 | AM28: 0.8125 | AN28: 216 | AO28: 0.8125 | AP28: 152 | AQ28: 0.79166667 | AR28: 71 | AS28: 0.8125
A29: 20 | B29: 345 | C29: 0.8125 | H29: 18 | I29: 0.8125 | J29: 17.5 | K29: 0.95833333 | L29: 1.9 | M29: 0.79166667 | N29: 198 | O29: 0.8125 | P29: 565 | Q29: 0.8125 | R29: 167 | S29: 0.8125 | T29: 147 | U29: 0.8125 | V29: 235 | W29: 0.8125 | X29: 38 | Y29: 0.45833333 | Z29: 56 | AA29: 0.54166667 | AB29: 145 | AC29: 0.54166667 | AD29: 31 | AE29: 0.5 | AF29: 67 | AG29: 0.83333333 | AH29: 30 | AI29: 0.8125 | AJ29: 50 | AK29: 0.58333333 | AL29: 78 | AM29: 0.79166667 | AN29: 225 | AO29: 0.79166667 | AP29: 161 | AQ29: 0.79166667 | AR29: 66 | AS29: 0.8125
A30: 21 | B30: 336 | C30: 0.8125 | H30: 18 | I30: 0.8125 | J30: 16.4 | K30: 0.83333333 | N30: 195 | O30: 0.8125 | P30: 557 | Q30: 0.8125 | R30: 167 | S30: 0.79166667 | T30: 150 | U30: 0.8125 | V30: 228 | W30: 0.8125 | X30: 39 | Y30: 0.45833333 | Z30: 55 | AA30: 0.8125 | AB30: 156 | AC30: 0.45833333 | AD30: 28 | AE30: 0.25 | AF30: 68 | AG30: 0.8125 | AH30: 31 | AI30: 0.875 | AJ30: 56 | AK30: 0.66666667 | AL30: 79 | AM30: 0.79166667 | AN30: 224 | AO30: 0.79166667 | AP30: 162 | AQ30: 0.79166667 | AR30: 64 | AS30: 0.83333333
A31: 22 | B31: 352 | C31: 0.79166667 | H31: 18 | I31: 0.79166667 | J31: 14.8 | K31: 0.41666667 | N31: 187 | O31: 0.79166667 | P31: 524 | Q31: 0.79166667 | R31: 159 | S31: 0.79166667 | T31: 145 | U31: 0.8125 | V31: 220 | W31: 0.79166667 | X31: 41 | Y31: 0.45833333 | Z31: 58 | AA31: 0.8125 | AB31: 163 | AC31: 0.8125 | AD31: 30 | AE31: 0.58333333 | AF31: 69 | AG31: 0.8125 | AH31: 30 | AI31: 0.79166667 | AJ31: 52 | AK31: 0.375 | AL31: 78 | AM31: 0.79166667 | AN31: 222 | AO31: 0.79166667 | AP31: 158 | AQ31: 0.77083333 | AR31: 64 | AS31: 0.79166667
A32: 23 | B32: 341 | C32: 0.8125 | H32: 19 | I32: 0.79166667 | J32: 15 | K32: 0.8125 | N32: 187 | O32: 0.8125 | P32: 512 | Q32: 0.8125 | R32: 161 | S32: 0.79166667 | T32: 141 | U32: 0.83333333 | V32: 220 | W32: 0.83333333 | X32: 38 | Y32: 0.41666667 | Z32: 56 | AA32: 0.83333333 | AB32: 157 | AC32: 0.83333333 | AD32: 60 | AE32: 0.95833333 | AF32: 69 | AG32: 0.8125 | AH32: 28 | AI32: 0.83333333 | AJ32: 52 | AK32: 0.45833333 | AL32: 73 | AM32: 0.79166667 | AN32: 216 | AO32: 0.79166667 | AP32: 155 | AQ32: 0.79166667 | AR32: 61 | AS32: 0.79166667
A33: 24 | B33: 346 | C33: 0.83333333 | H33: 19 | I33: 0.83333333 | J33: 18.5 | K33: 0.75 | N33: 192 | O33: 0.8125 | P33: 505 | Q33: 0.8125 | R33: 156 | S33: 0.79166667 | T33: 139 | U33: 19:00 | V33: 216 | W33: 0.79166667 | X33: 22 | Y33: 0.33333333 | Z33: 58 | AA33: 0.83333333 | AB33: 146 | AC33: 0.83333333 | AD33: 40 | AE33: 0.66666667 | AF33: 68 | AG33: 0.83333333 | AH33: 30 | AI33: 0.8125 | AJ33: 16 | AK33: 0.70833333 | AL33: 79 | AM33: 0.79166667 | AN33: 211 | AO33: 0.79166667 | AP33: 150 | AQ33: 0.79166667 | AR33: 67 | AS33: 0.83333333
A34: 25 | B34: 360 | C34: 0.8125 | H34: 20 | I34: 0.8125 | J34: 16 | K34: 0.083333333 | L34: 1.2 | M34: 0.5 | N34: 194 | O34: 0.79166667 | P34: 549 | Q34: 0.79166667 | R34: 163 | S34: 0.79166667 | T34: 149 | U34: 0.83333333 | V34: 234 | W34: 0.8125 | X34: 36 | Y34: 0.41666667 | Z34: 55 | AA34: 0.79166667 | AB34: 166 | AC34: 0.79166667 | AD34: 61 | AE34: 0.95833333 | AF34: 71 | AG34: 0.79166667 | AH34: 31 | AI34: 0.8125 | AJ34: 38 | AK34: 0.41666667 | AL34: 77 | AM34: 0.8125 | AN34: 231 | AO34: 0.79166667 | AP34: 163 | AQ34: 0.79166667 | AR34: 67 | AS34: 0.79166667
A35: 26 | B35: 350 | C35: 0.79166667 | H35: 20 | I35: 0.79166667 | J35: 17.1 | K35: 0.72916667 | N35: 195 | O35: 0.8125 | P35: 540 | Q35: 0.8125 | R35: 164 | S35: 0.79166667 | T35: 149 | U35: 0.83333333 | V35: 227 | W35: 0.8125 | X35: 37 | Y35: 0.41666667 | Z35: 55 | AA35: 0.79166667 | AB35: 155 | AC35: 0.79166667 | AD35: 34 | AE35: 0.20833333 | AF35: 67 | AG35: 0.8125 | AH35: 33 | AI35: 0.8125 | AJ35: 42 | AK35: 0.54166667 | AL35: 78 | AM35: 0.79166667 | AN35: 218 | AO35: 0.79166667 | AP35: 155 | AQ35: 0.79166667 | AR35: 65 | AS35: 0.8125
A36: 27 | B36: 361 | C36: 0.79166667 | H36: 19 | I36: 0.70833333 | J36: 15 | K36: 0.79166667 | N36: 203 | O36: 0.8125 | P36: 551 | Q36: 0.8125 | R36: 167 | S36: 0.79166667 | T36: 149 | U36: 0.8125 | V36: 234 | W36: 0.8125 | X36: 37 | Y36: 0.45833333 | Z36: 58 | AA36: 0.54166667 | AB36: 158 | AC36: 0.54166667 | AD36: 35 | AE36: 0.33333333 | AF36: 72 | AG36: 0.8125 | AH36: 34 | AI36: 0.83333333 | AJ36: 48 | AK36: 0.66666667 | AL36: 81 | AM36: 0.79166667 | AN36: 230 | AO36: 0.79166667 | AP36: 164 | AQ36: 0.79166667 | AR36: 66 | AS36: 0.8125
A37: 28 | B37: 302 | C37: 0.83333333 | H37: 16 | I37: 0.79166667 | J37: 22.7 | K37: 0.79166667 | L37: 1.4 | M37: 0.29166667 | N37: 172 | O37: 0.79166667 | P37: 475 | Q37: 0.79166667 | R37: 146 | S37: 0.79166667 | T37: 133 | U37: 0.8125 | V37: 194 | W37: 0.79166667 | X37: 37 | Y37: 0.45833333 | Z37: 58 | AA37: 0.83333333 | AB37: 163 | AC37: 0.83333333 | AD37: 50 | AE37: 0.33333333 | AF37: 66 | AG37: 0.8125 | AH37: 29 | AI37: 0.8125 | AJ37: 52 | AK37: 0.41666667 | AL37: 70 | AM37: 0.79166667 | AN37: 198 | AO37: 0.79166667 | AP37: 143 | AQ37: 0.79166667 | AR37: 55 | AS37: 0.79166667
A38: 29 | B38: 325 | C38: 0.8125 | H38: 21 | I38: 0.8125 | J38: 23 | K38: 0.8125 | N38: 180 | O38: 0.8125 | P38: 501 | Q38: 0.8125 | R38: 153 | S38: 0.8125 | T38: 135 | U38: 0.83333333 | V38: 2120 | W38: 0.8125 | X38: 35 | Y38: 0.45833333 | Z38: 65 | AA38: 0.54166667 | AB38: 182 | AC38: 0.54166667 | AD38: 39 | AE38: 0.25 | AF38: 100 | AG38: 0.58333333 | AH38: 30 | AI38: 0.8125 | AJ38: 45 | AK38: 0.41666667 | AL38: 79 | AM38: 0.79166667 | AN38: 209 | AO38: 0.79166667 | AP38: 151 | AQ38: 0.79166667 | AR38: 62 | AS38: 0.8125
A39: 30 | B39: 360 | C39: 0.77083333 | H39: 52 | I39: 0.45833333 | J39: 20.6 | K39: 0.54166667 | N39: 198 | O39: 0.79166667 | P39: 537 | Q39: 0.79166667 | R39: 167 | S39: 0.79166667 | T39: 148 | U39: 19;30 | V39: 225 | W39: 0.8125 | X39: 41 | Y39: 0.45833333 | Z39: 55 | AA39: 0.8125 | AB39: 157 | AC39: 0.8125 | AD39: 29 | AE39: 0.041666667 | AF39: 68 | AG39: 0.79166667 | AH39: 29 | AI39: 0.83333333 | AJ39: 45 | AK39: 0.66666667 | AL39: 82 | AM39: 0.79166667 | AN39: 235 | AO39: 0.79166667 | AP39: 170 | AQ39: 0.79166667 | AR39: 65 | AS39: 0.8125
A40: 31 | B40: 369 | C40: 0.79166667 | H40: 21 | I40: 0.79166667 | J40: 22.9 | K40: 0.83333333 | N40: 200 | O40: 0.8125 | P40: 559 | Q40: 0.8125 | R40: 166 | S40: 0.8125 | T40: 155 | U40: 0.8125 | V40: 241 | W40: 0.8125 | X40: 21 | Y40: 0.5 | Z40: 58 | AA40: 0.8125 | AB40: 156 | AC40: 0.8125 | AD40: 34 | AE40: 0.41666667 | AF40: 72 | AG40: 0.83333333 | AH40: 31 | AI40: 0.875 | AJ40: 16 | AK40: 0.5 | AL40: 89 | AM40: 0.79166667 | AN40: 231 | AO40: 0.79166667 | AP40: 163 | AQ40: 0.79166667 | AR40: 69 | AS40: 0.79166667
A41: 32
A44: Monthly | B44: =MAX(B10:B41) -> 444 | D44: =MAX(D10:D41) -> 0 | F44: =MAX(F10:F41) -> 0 | H44: =MAX(H10:H41) -> 52 | J44: =MAX(J10:J41) -> 23 | L44: =MAX(L10:L41) -> 6.1 | N44: =MAX(N10:N41) -> 239 | P44: =MAX(P10:P41) -> 637 | R44: =MAX(R10:R41) -> 195 | T44: =MAX(T10:T41) -> 175 | V44: =MAX(V10:V41) -> 2120 | X44: =MAX(X10:X41) -> 45 | Z44: =MAX(Z10:Z41) -> 79 | AB44: =MAX(AB10:AB41) -> 215 | AD44: =MAX(AD10:AD41) -> 61 | AF44: =MAX(AF10:AF41) -> 128 | AH44: =MAX(AH10:AH41) -> 71 | AJ44: =MAX(AJ10:AJ41) -> 60 | AL44: =MAX(AL10:AL41) -> 98 | AN44: =MAX(AN10:AN41) -> 267 | AP44: =MAX(AP10:AP41) -> 192 | AR44: =MAX(AR10:AR41) -> 78
A49: …………….. …………….. ……………..
...

Sheet Bhadra
A1: NEPAL ELECTRICITY AUTHORITY
A2: DHARAN DISTRIBUTION CENTER
A4: Peak Load Details
A6: Month: | B6: Bhadra | C6: 2082
A8: Day | B8: 33KV Duhabi-Dharan | F8: 33KV Dharan-Dhankuta | J8: 33KV Dharan-Chatara Bayarban | N8: 33/11KV, 16.6MVA Power Trf 1 | P8: 11KV Incomer 1 | R8: Dharan | T8: Bagarkot | V8: Local Chatara | X8: BPKIHS | Z8: 33/11KV, 8MVA Power Trf 2 | AB8: 11KV Incomer 2 | AD8: Khanepani | AF8: Railway | AH8: British | AJ8: Industrial | AL8: 33/11KV, 8MVA Power Trf 3 | AN8: 11KV Incomer 3 | AP8: Bhanu | AR8: Panmara
B9: Max. Import (A) | C9: Time | D9: Max. Export (A) | E9: Time | F9: Max. Import (A) | G9: Time | H9: Max. Export (A) | I9: Time | J9: Max. Import (A) | K9: Time | L9: Max. Export (A) | M9: Time | N9: Max. (A) | O9: Time | P9: Max. (A) | Q9: Time | R9: Max. (A) | S9: Time | T9: Max. (A) | U9: Time | V9: Max. (A) | W9: Time | X9: Max. (A) | Y9: Time | Z9: Max. (A) | AA9: Time | AB9: Max. (A) | AC9: Time | AD9: Max. (A) | AE9: Time | AF9: Max. (A) | AG9: Time | AH9: Max. (A) | AI9: Time | AJ9: Max. (A) | AK9: Time | AL9: Max. (A) | AM9: Time | AN9: Max. (A) | AO9: Time | AP9: Max. (A) | AQ9: Time | AR9: Max. (A) | AS9: Time
A10: 1 | B10: 369 | C10: 0.79166667 | H10: 17 | I10: 0.29166667 | J10: 36 | K10: 0.79166667 | N10: 211 | O10: 0.79166667 | P10: 592 | Q10: 0.79166667 | R10: 178 | S10: 0.79166667 | T10: 157 | U10: 0.8125 | V10: 250 | W10: 0.79166667 | X10: 38 | Y10: 0.45833333 | Z10: 57 | AA10: 0.45833333 | AB10: 157 | AC10: 0.45833333 | AD10: 34 | AE10: 0.45833333 | AF10: 73 | AG10: 0.79166667 | AH10: 52 | AI10: 0.58333333 | AJ10: 38 | AK10: 0.375 | AL10: 86 | AM10: 0.79166667 | AN10: 249 | AO10: 0.79166667 | AP10: 175 | AQ10: 0.79166667 | AR10: 70 | AS10: 0.79166667
A11: 2 | B11: 310 | C11: 0.8125 | J11: 23.8 | K11: 0.5 | N11: 196 | O11: 0.8125 | P11: 535 | Q11: 0.8125 | R11: 168 | S11: 0.79166667 | T11: 147 | U11: 0.83333333 | V11: 228 | W11: 0.8125 | X11: 42 | Y11: 0.41666667 | Z11: 51 | AA11: 0.5 | AB11: 142 | AC11: 0.79166667 | AD11: 32 | AE11: 0.5 | AF11: 66 | AG11: 0.8125 | AH11: 32 | AI11: 0.8125 | AJ11: 47 | AK11: 0.45833333 | AL11: 81 | AM11: 0.79166667 | AN11: 225 | AO11: 0.79166667 | AP11: 160 | AQ11: 0.79166667 | AR11: 65 | AS11: 0.79166667
A12: 3 | B12: 326 | C12: 0.8125 | H12: 8 | I12: 0.70833333 | J12: 23 | K12: 0.41666667 | N12: 189 | O12: 0.8125 | P12: 523 | Q12: 0.8125 | R12: 158 | S12: 0.79166667 | T12: 141 | U12: 0.83333333 | V12: 218 | W12: 0.8125 | X12: 40 | Y12: 0.41666667 | Z12: 57 | AA12: 0.83333333 | AB12: 160 | AC12: 0.83333333 | AD12: 39 | AE12: 0.29166667 | AF12: 67 | AG12: 0.79166667 | AH12: 32 | AI12: 0.83333333 | AJ12: 49 | AK12: 0.66666667 | AL12: 78 | AM12: 0.79166667 | AN12: 221 | AO12: 0.79166667 | AP12: 162 | AQ12: 0.79166667 | AR12: 60 | AS12: 0.8125
A13: 4 | B13: 350 | C13: 0.79166667 | H13: 18 | I13: 0.79166667 | J13: 21 | K13: 0.16666667 | N13: 200 | O13: 0.79166667 | P13: 555 | Q13: 0.79166667 | R13: 172 | S13: 0.79166667 | T13: 148 | U13: 0.79166667 | V13: 233 | W13: 0.79166667 | X13: 39 | Y13: 0.41666667 | Z13: 53 | AA13: 0.54166667 | AB13: 153 | AC13: 0.54166667 | AD13: 35 | AE13: 0.33333333 | AF13: 72 | AG13: 0.8125 | AH13: 31 | AI13: 0.8125 | AJ13: 56 | AK13: 0.58333333 | AL13: 81 | AM13: 0.79166667 | AN13: 232 | AO13: 0.79166667 | AP13: 167 | AQ13: 0.79166667 | AR13: 64 | AS13: 0.79166667
A14: 5 | B14: 345 | C14: 0.79166667 | H14: 17 | I14: 0.79166667 | J14: 18 | K14: 0.041666667 | N14: 200 | O14: 0.79166667 | P14: 547 | Q14: 0.79166667 | R14: 168 | S14: 0.79166667 | T14: 148 | U14: 0.79166667 | V14: 230 | W14: 0.8125 | X14: 39 | Y14: 0.41666667 | Z14: 56 | AA14: 0.5 | AB14: 150 | AC14: 0.5 | AD14: 39 | AE14: 0.20833333 | AF14: 63 | AG14: 0.83333333 | AH14: 33 | AI14: 0.875 | AJ14: 52 | AK14: 0.79166667 | AL14: 81 | AM14: 0.79166667 | AN14: 229 | AO14: 0.79166667 | AP14: 166 | AQ14: 0.79166667 | AR14: 63 | AS14: 0.79166667
A15: 6 | B15: 355 | C15: 0.79166667 | H15: 20 | I15: 0.8125 | J15: 18.2 | K15: 0.79166667 | N15: 200 | O15: 0.79166667 | P15: 567 | Q15: 0.79166667 | R15: 169 | S15: 0.79166667 | T15: 151 | U15: 0.8125 | V15: 234 | W15: 0.8125 | X15: 38 | Y15: 0.45833333 | Z15: 58 | AA15: 0.45833333 | AB15: 164 | AC15: 0.45833333 | AD15: 35 | AE15: 0.45833333 | AF15: 69 | AG15: 0.79166667 | AH15: 30 | AI15: 0.8125 | AJ15: 60 | AK15: 0.375 | AL15: 81 | AM15: 0.79166667 | AN15: 232 | AO15: 0.79166667 | AP15: 168 | AQ15: 0.79166667 | AR15: 64 | AS15: 0.79166667
A16: 7 | B16: 346 | C16: 0.8125 | H16: 22 | I16: 0.8125 | J16: 17 | K16: 0.125 | N16: 196 | O16: 0.8125 | P16: 539 | Q16: 0.8125 | R16: 169 | S16: 0.8125 | T16: 146 | U16: 0.875 | V16: 236 | W16: 0.8125 | X16: 20 | Y16: 0.33333333 | Z16: 50 | AA16: 0.8125 | AB16: 141 | AC16: 0.8125 | AD16: 36 | AE16: 0.25 | AF16: 71 | AG16: 0.79166667 | AH16: 30 | AI16: 0.875 | AJ16: 23 | AK16: 0.625 | AL16: 82 | AM16: 0.8125 | AN16: 226 | AO16: 0.79166667 | AP16: 159 | AQ16: 0.8125 | AR16: 63 | AS16: 0.79166667
A17: 8 | B17: 369 | C17: 0.79166667 | H17: 26 | I17: 0.79166667 | J17: 13.4 | K17: 0.54166667 | N17: 206 | O17: 0.79166667 | P17: 543 | Q17: 0.79166667 | R17: 170 | S17: 0.79166667 | T17: 149 | U17: 0.875 | V17: 228 | W17: 0.79166667 | X17: 39 | Y17: 0.625 | Z17: 58 | AA17: 0.41666667 | AB17: 157 | AC17: 0.41666667 | AD17: 40 | AE17: 0.375 | AF17: 70 | AG17: 0.8125 | AH17: 31 | AI17: 0.83333333 | AJ17: 62 | AK17: 0.41666667 | AL17: 86 | AM17: 0.79166667 | AN17: 227 | AO17: 0.79166667 | AP17: 164 | AQ17: 0.79166667 | AR17: 63 | AS17: 0.79166667
A18: 9 | B18: 360 | C18: 0.79166667 | H18: 19 | I18: 0.79166667 | J18: 13.9 | K18: 0.79166667 | N18: 202 | O18: 0.79166667 | P18: 552 | Q18: 0.79166667 | R18: 170 | S18: 0.79166667 | T18: 147 | U18: 0.8125 | V18: 234 | W18: 0.79166667 | X18: 48 | Y18: 0.54166667 | Z18: 59 | AA18: 0.54166667 | AB18: 156 | AC18: 0.54166667 | AD18: 34 | AE18: 0.20833333 | AF18: 70 | AG18: 0.79166667 | AH18: 31 | AI18: 0.8125 | AJ18: 49 | AK18: 0.45833333 | AL18: 80 | AM18: 0.79166667 | AN18: 227 | AO18: 0.79166667 | AP18: 164 | AQ18: 0.79166667 | AR18: 65 | AS18: 0.8125
A19: 10 | B19: 337 | C19: 0.79166667 | H19: 19 | I19: 0.79166667 | J19: 18.3 | K19: 0.33333333 | N19: 186 | O19: 0.79166667 | P19: 512 | Q19: 0.79166667 | R19: 156 | S19: 0.79166667 | T19: 138 | U19: 0.8125 | V19: 213 | W19: 0.79166667 | X19: 37 | Y19: 0.41666667 | Z19: 58 | AA19: 0.41666667 | AB19: 189 | AC19: 0.41666667 | AD19: 32 | AE19: 0.20833333 | AF19: 68 | AG19: 0.8125 | AH19: 30 | AI19: 0.8125 | AJ19: 48 | AK19: 0.375 | AL19: 80 | AM19: 0.79166667 | AN19: 214 | AO19: 0.79166667 | AP19: 151 | AQ19: 0.79166667 | AR19: 61 | AS19: 0.79166667
A20: 11 | B20: 338 | C20: 0.77083333 | H20: 18 | I20: 0.77083333 | J20: 19.6 | K20: 0.91666667 | N20: 190 | O20: 0.8125 | P20: 525 | Q20: 0.8125 | R20: 158 | S20: 0.79166667 | T20: 138 | U20: 0.8125 | V20: 219 | W20: 0.79166667 | X20: 38 | Y20: 0.41666667 | Z20: 52 | AA20: 0.79166667 | AB20: 142 | AC20: 0.79166667 | AD20: 34 | AE20: 0.5 | AF20: 65 | AG20: 0.79166667 | AH20: 31 | AI20: 0.79166667 | AJ20: 48 | AK20: 0.45833333 | AL20: 75 | AM20: 0.79166667 | AN20: 208 | AO20: 0.79166667 | AP20: 149 | AQ20: 0.79166667 | AR20: 59 | AS20: 0.77083333
A21: 12 | B21: 350 | C21: 0.79166667 | H21: 18 | I21: 0.79166667 | J21: 16.4 | K21: 0.54166667 | N21: 194 | O21: 0.79166667 | P21: 519 | Q21: 0.79166667 | R21: 167 | S21: 0.79166667 | T21: 140 | U21: 0.79166667 | V21: 228 | W21: 0.79166667 | X21: 40 | Y21: 0.45833333 | Z21: 54 | AA21: 0.79166667 | AB21: 150 | AC21: 0.79166667 | AD21: 32 | AE21: 0.25 | AF21: 72 | AG21: 0.79166667 | AH21: 30 | AI21: 0.83333333 | AJ21: 53 | AK21: 0.66666667 | AL21: 78 | AM21: 0.79166667 | AN21: 225 | AO21: 0.79166667 | AP21: 163 | AQ21: 0.79166667 | AR21: 63 | AS21: 0.79166667
A22: 13 | B22: 337 | C22: 0.79166667 | H22: 20 | I22: 0.79166667 | J22: 20.3 | K22: 0.66666667 | N22: 193 | O22: 0.79166667 | P22: 536 | Q22: 0.79166667 | R22: 164 | S22: 0.79166667 | T22: 143 | U22: 0.79166667 | V22: 226 | W22: 0.79166667 | X22: 35 | Y22: 0.41666667 | Z22: 52 | AA22: 0.375 | AB22: 149 | AC22: 0.375 | AD22: 33 | AE22: 0.5 | AF22: 69 | AG22: 0.79166667 | AH22: 31 | AI22: 0.83333333 | AJ22: 48 | AK22: 0.66666667 | AL22: 78 | AM22: 0.8125 | AN22: 222 | AO22: 0.8125 | AP22: 160 | AQ22: 0.8125 | AR22: 62 | AS22: 0.79166667
A23: 14 | B23: 323 | C23: 0.79166667 | H23: 20 | I23: 0.79166667 | J23: 20 | K23: 0.33333333 | N23: 188 | O23: 0.79166667 | P23: 518 | Q23: 0.79166667 | R23: 159 | S23: 0.79166667 | T23: 141 | U23: 0.79166667 | V23: 218 | W23: 0.79166667 | X23: 19 | Y23: 0.45833333 | Z23: 39 | AA23: 0.8125 | AB23: 107 | AC23: 0.8125 | AD23: 35 | AE23: 0.20833333 | AF23: 69 | AG23: 0.8125 | AH23: 31 | AI23: 0.875 | AJ23: 14 | AK23: 0.41666667 | AL23: 76 | AM23: 0.79166667 | AN23: 213 | AO23: 0.79166667 | AP23: 153 | AQ23: 0.77083333 | AR23: 62 | AS23: 0.8125
... A31: 22 | B31: 349 | C31: 0.79166667 | H31: 19 | I31: 0.79166667 | J31: 21.9 | K31: 0.41666667 | N31: 187 | O31: 0.79166667 | P31: 530 | Q31: 0.79166667 | R31: 175 | S31: 0.79166667 | T31: 144 | U31: 0.83333333 | V31: 227 | W31: 0.79166667 | X31: 12 | Y31: 0.25 | Z31: 63 | AA31: 0.33333333 | AB31: 182 | AC31: 0.33333333 | AD31: 33 | AE31: 0.20833333 | AF31: 67 | AG31: 0.8125 | AH31: 61 | AI31: 0.375 | AJ31: 56 | AK31: 0.45833333 | AL31: 78 | AM31: 0.79166667 | AN31: 223 | AO31: 0.79166667 | AP31: 162 | AQ31: 0.79166667 | AR31: 61 | AS31: 0.79166667
A32: 23 | B32: 347 | C32: 0.79166667 | H32: 29 | I32: 0.5 | J32: 22.8 | K32: 0.125 | N32: 189 | O32: 0.79166667 | P32: 518 | Q32: 0.79166667 | R32: 169 | S32: 0.79166667 | T32: 139 | U32: 0.79166667 | V32: 223 | W32: 0.79166667 | Z32: 64 | AA32: 0.8125 | AB32: 186 | AC32: 0.95833333 | AD32: 33 | AE32: 0.5 | AF32: 64 | AG32: 0.8125 | AH32: 63 | AI32: 0.41666667 | AJ32: 51 | AK32: 0.66666667 | AL32: 77 | AM32: 0.79166667 | AN32: 220 | AO32: 0.79166667 | AP32: 158 | AQ32: 0.79166667 | AR32: 61 | AS32: 0.79166667
A33: 24 | B33: 310 | C33: 0.77083333 | H33: 19 | I33: 0.79166667 | J33: 22.4 | K33: 0.5 | N33: 186 | O33: 0.77083333 | P33: 510 | Q33: 0.77083333 | R33: 147 | S33: 0.77083333 | T33: 134 | U33: 0.77083333 | V33: 212 | W33: 0.77083333 | X33: 36 | Y33: 0.5 | Z33: 66 | AA33: 0.33333333 | AB33: 188 | AC33: 0.29166667 | AD33: 34 | AE33: 0.5 | AF33: 98 | AG33: 0.041666667 | AH33: 63 | AI33: 0.41666667 | AJ33: 50 | AK33: 0.41666667 | AL33: 68 | AM33: 0.45833333 | AN33: 185 | AO33: 0.45833333 | AP33: 145 | AQ33: 0.45833333 | AR33: 61 | AS33: 0.77083333
A34: 25 | B34: 300 | C34: 0.77083333 | J34: 21.6 | K34: 0.77083333 | N34: 189 | O34: 0.77083333 | P34: 522 | Q34: 0.77083333 | R34: 141 | S34: 0.77083333 | T34: 143 | U34: 0.77083333 | V34: 223 | W34: 0.77083333 | X34: 33 | Y34: 0.375 | Z34: 55 | AA34: 0.79166667 | AB34: 145 | AC34: 0.79166667 | AD34: 39 | AE34: 0.58333333 | AF34: 65 | AG34: 0.77083333 | AH34: 33 | AI34: 0.77083333 | AJ34: 44 | AK34: 0.625 | AL34: 68 | AM34: 0.77083333 | AN34: 190 | AO34: 0.77083333 | AP34: 124 | AQ34: 0.77083333 | AR34: 65 | AS34: 0.77083333
A35: 26 | B35: 331 | C35: 0.8125 | J35: 22.2 | K35: 0.875 | N35: 171 | O35: 0.77083333 | P35: 477 | Q35: 0.77083333 | R35: 140 | S35: 0.77083333 | T35: 131 | U35: 0.79166667 | V35: 219 | W35: 0.79166667 | X35: 39 | Y35: 0.375 | Z35: 59 | AA35: 0.41666667 | AB35: 161 | AC35: 0.41666667 | AD35: 38 | AE35: 0.375 | AF35: 57 | AG35: 0.45833333 | AH35: 31 | AI35: 0.77083333 | AJ35: 45 | AK35: 0.375 | AL35: 64 | AM35: 0.75 | AN35: 179 | AO35: 0.75 | AP35: 124 | AQ35: 0.77083333 | AR35: 56 | AS35: 0.79166667
A36: 27 | B36: 316 | C36: 0.77083333 | H36: 17 | I36: 0.77083333 | J36: 20.6 | K36: 0.41666667 | N36: 188 | O36: 0.79166667 | P36: 521 | Q36: 0.79166667 | R36: 145 | S36: 0.77083333 | T36: 147 | U36: 0.79166667 | V36: 222 | W36: 0.8125 | X36: 37 | Y36: 0.375 | Z36: 49 | AA36: 0.8125 | AB36: 141 | AC36: 0.8125 | AD36: 36 | AE36: 0.041666667 | AF36: 61 | AG36: 0.77083333 | AH36: 32 | AI36: 0.79166667 | AJ36: 50 | AK36: 0.45833333 | AL36: 74 | AM36: 0.8125 | AN36: 189 | AO36: 0.8125 | AP36: 134 | AQ36: 0.75 | AR36: 64 | AS36: 0.79166667
A37: 28 | B37: 291 | C37: 0.79166667 | H37: 33 | I37: 0.45833333 | J37: 22.8 | K37: 0.54166667 | N37: 179 | O37: 0.77083333 | P37: 488 | Q37: 0.77083333 | R37: 140 | S37: 0.77083333 | T37: 136 | U37: 0.79166667 | V37: 211 | W37: 0.77083333 | X37: 21 | Y37: 0.5 | Z37: 56 | AA37: 0.8125 | AB37: 150 | AC37: 0.8125 | AD37: 31 | AE37: 0.95833333 | AF37: 70 | AG37: 0.77083333 | AH37: 29 | AI37: 0.79166667 | AJ37: 18 | AK37: 0.45833333 | AL37: 70 | AM37: 0.77083333 | AN37: 190 | AO37: 0.77083333 | AP37: 132 | AQ37: 0.77083333 | AR37: 62 | AS37: 0.77083333
A38: 29 | B38: 318 | C38: 0.8125 | H38: 22 | I38: 0.75 | J38: 23.8 | K38: 0.79166667 | N38: 181 | O38: 0.77083333 | P38: 499 | Q38: 0.77083333 | R38: 155 | S38: 0.77083333 | T38: 132 | U38: 0.79166667 | V38: 216 | W38: 0.77083333 | X38: 38 | Y38: 0.41666667 | Z38: 54 | AA38: 0.375 | AB38: 151 | AC38: 0.375 | AD38: 41 | AE38: 0.45833333 | AF38: 96 | AG38: 0.77083333 | AH38: 31 | AI38: 0.8125 | AJ38: 49 | AK38: 0.375 | AL38: 74 | AM38: 0.77083333 | AN38: 216 | AO38: 0.77083333 | AP38: 150 | AQ38: 0.77083333 | AR38: 60 | AS38: 0.77083333
A39: 30 | B39: 335 | C39: 0.77083333 | H39: 17 | I39: 0.41666667 | J39: 23 | K39: 0.83333333 | N39: 177 | O39: 0.77083333 | P39: 487 | Q39: 0.77083333 | R39: 153 | S39: 0.77083333 | T39: 127 | U39: 0.77083333 | V39: 202 | W39: 0.77083333 | X39: 39 | Y39: 0.45833333 | Z39: 55 | AA39: 0.5 | AB39: 150 | AC39: 0.5 | AD39: 44 | AE39: 0.58333333 | AF39: 62 | AG39: 0.77083333 | AH39: 27 | AI39: 0.77083333 | AJ39: 52 | AK39: 0.41666667 | AL39: 73 | AM39: 0.77083333 | AN39: 204 | AO39: 0.77083333 | AP39: 149 | AQ39: 0.77083333 | AR39: 55 | AS39: 0.77083333
A40: 31 | B40: 306 | C40: 0.79166667 | H40: 18 | I40: 0.77083333 | J40: 21.3 | K40: 0.33333333 | N40: 174 | O40: 0.77083333 | P40: 475 | Q40: 0.77083333 | R40: 145 | S40: 0.79166667 | T40: 130 | U40: 0.79166667 | V40: 204 | W40: 0.77083333 | X40: 37 | Y40: 0.45833333 | Z40: 52 | AA40: 0.875 | AB40: 149 | AC40: 0.875 | AD40: 31 | AE40: 0.45833333 | AF40: 60 | AG40: 0.77083333 | AH40: 27 | AI40: 0.79166667 | AJ40: 30 | AK40: 0.29166667 | AL40: 75 | AM40: 0.77083333 | AN40: 207 | AO40: 0.77083333 | AP40: 151 | AQ40: 0.77083333 | AR40: 56 | AS40: 0.77083333
A41: 32
A44: Monthly | B44: =MAX(B10:B41) -> 382 | D44: =MAX(D10:D41) -> 0 | F44: =MAX(F10:F41) -> 0 | H44: =MAX(H10:H41) -> 50 | J44: =MAX(J10:J41) -> 36 | L44: =MAX(L10:L41) -> 0 | N44: =MAX(N10:N41) -> 220 | P44: =MAX(P10:P41) -> 610 | R44: =MAX(R10:R41) -> 183 | T44: =MAX(T10:T41) -> 162 | V44: =MAX(V10:V41) -> 260 | X44: =MAX(X10:X41) -> 48 | Z44: =MAX(Z10:Z41) -> 78 | AB44: =MAX(AB10:AB41) -> 212 | AD44: =MAX(AD10:AD41) -> 45 | AF44: =MAX(AF10:AF41) -> 133 | AH44: =MAX(AH10:AH41) -> 63 | AJ44: =MAX(AJ10:AJ41) -> 62 | AL44: =MAX(AL10:AL41) -> 90 | AN44: =MAX(AN10:AN41) -> 253 | AP44: =MAX(AP10:AP41) -> 185 | AR44: =MAX(AR10:AR41) -> 70
A49: …………….. …………….. ……………..
A50: Prepared by Checked by Approved by

Sheet Ashoj
A1: NEPAL ELECTRICITY AUTHORITY
A2: DHARAN DISTRIBUTION CENTER
A4: Peak Load Details
A6: Month: | B6: Ashoj | C6: 2082
A8: Day | B8: 33KV Duhabi-Dharan | F8: 33KV Dharan-Dhankuta | J8: 33KV Dharan-Chatara Bayarban | N8: 33/11KV, 16.6MVA Power Trf 1 | P8: 11KV Incomer 1 | R8: Dharan | T8: Bagarkot | V8: Local Chatara | X8: BPKIHS | Z8: 33/11KV, 8MVA Power Trf 2 | AB8: 11KV Incomer 2 | AD8: Khanepani | AF8: Railway | AH8: British | AJ8: Industrial | AL8: 33/11KV, 8MVA Power Trf 3 | AN8: 11KV Incomer 3 | AP8: Bhanu | AR8: Panmara
B9: Max. Import (A) | C9: Time | D9: Max. Export (A) | E9: Time | F9: Max. Import (A) | G9: Time | H9: Max. Export (A) | I9: Time | J9: Max. Import (A) | K9: Time | L9: Max. Export (A) | M9: Time | N9: Max. (A) | O9: Time | P9: Max. (A) | Q9: Time | R9: Max. (A) | S9: Time | T9: Max. (A) | U9: Time | V9: Max. (A) | W9: Time | X9: Max. (A) | Y9: Time | Z9: Max. (A) | AA9: Time | AB9: Max. (A) | AC9: Time | AD9: Max. (A) | AE9: Time | AF9: Max. (A) | AG9: Time | AH9: Max. (A) | AI9: Time | AJ9: Max. (A) | AK9: Time | AL9: Max. (A) | AM9: Time | AN9: Max. (A) | AO9: Time | AP9: Max. (A) | AQ9: Time | AR9: Max. (A) | AS9: Time
A10: 1 | B10: 350 | C10: 0.77083333 | H10: 19 | I10: 0.79166667 | J10: 26.7 | K10: 0.58333333 | N10: 191 | O10: 0.79166667 | P10: 532 | Q10: 0.79166667 | R10: 158 | S10: 0.77083333 | T10: 139 | U10: 0.77083333 | V10: 226 | W10: 0.79166667 | X10: 23 | Y10: 0.54166667 | Z10: 64 | AA10: 0.79166667 | AB10: 180 | AC10: 0.79166667 | AD10: 35 | AE10: 0.33333333 | AF10: 114 | AG10: 0.79166667 | AH10: 30 | AI10: 0.79166667 | AJ10: 7 | AK10: 0.25 | AL10: 74 | AM10: 0.77083333 | AN10: 206 | AO10: 0.77083333 | AP10: 146 | AQ10: 0.77083333 | AR10: 61 | AS10: 0.77083333
A11: 2 | B11: 331 | C11: 0.77083333 | H11: 18 | I11: 0.77083333 | J11: 24.5 | K11: 0.79166667 | N11: 176 | O11: 0.77083333 | P11: 493 | Q11: 0.77083333 | R11: 146 | S11: 0.77083333 | T11: 131 | U11: 0.77083333 | V11: 210 | W11: 0.77083333 | X11: 37 | Y11: 0.45833333 | Z11: 64 | AA11: 0.625 | AB11: 176 | AC11: 0.625 | AD11: 34 | AE11: 0.25 | AF11: 110 | AG11: 0.77083333 | AH11: 27 | AI11: 0.79166667 | AJ11: 37 | AK11: 0.54166667 | AL11: 74 | AM11: 0.77083333 | AN11: 210 | AO11: 0.77083333 | AP11: 153 | AQ11: 0.77083333 | AR11: 58 | AS11: 0.77083333
A12: 3 | B12: 338 | C12: 0.77083333 | H12: 22 | I12: 0.77083333 | J12: 21.2 | K12: 0.54166667 | N12: 180 | O12: 0.77083333 | P12: 500 | Q12: 0.77083333 | R12: 151 | S12: 0.77083333 | T12: 136 | U12: 0.79166667 | V12: 213 | W12: 0.77083333 | X12: 20 | Y12: 0.375 | Z12: 63 | AA12: 0.8125 | AB12: 177 | AC12: 0.8125 | AD12: 35 | AE12: 0.29166667 | AF12: 104 | AG12: 0.8125 | AH12: 26 | AI12: 0.83333333 | AJ12: 45 | AK12: 0.375 | AL12: 76 | AM12: 0.77083333 | AN12: 213 | AO12: 0.77083333 | AP12: 150 | AQ12: 0.77083333 | AR12: 61 | AS12: 0.77083333
A13: 4 | B13: 364 | C13: 0.77083333 | H13: 19 | I13: 0.77083333 | J13: 22.3 | K13: 0.77083333 | N13: 188 | O13: 0.79166667 | P13: 539 | Q13: 0.79166667 | R13: 160 | S13: 0.77083333 | T13: 142 | U13: 0.79166667 | V13: 228 | W13: 0.79166667 | X13: 19 | Y13: 0.5 | Z13: 74 | AA13: 0.77083333 | AB13: 216 | AC13: 0.77083333 | AD13: 32 | AE13: 0.25 | AF13: 141 | AG13: 0.77083333 | AH13: 29 | AI13: 0.79166667 | AJ13: 20 | AK13: 0.45833333 | AL13: 83 | AM13: 0.77083333 | AN13: 232 | AO13: 0.77083333 | AP13: 163 | AQ13: 0.77083333 | AR13: 69 | AS13: 0.77083333
A14: 5 | B14: 379 | C14: 0.77083333 | H14: 26 | I14: 0.77083333 | J14: 21.5 | K14: 0.375 | N14: 199 | O14: 0.77083333 | P14: 535 | Q14: 0.77083333 | R14: 163 | S14: 0.77083333 | T14: 141 | U14: 0.77083333 | V14: 226 | W14: 0.77083333 | X14: 40 | Y14: 0.41666667 | Z14: 67 | AA14: 0.77083333 | AB14: 173 | AC14: 0.77083333 | AD14: 34 | AE14: 0.33333333 | AF14: 123 | AG14: 0.77083333 | AH14: 28 | AI14: 0.8125 | AJ14: 43 | AK14: 0.45833333 | AL14: 94 | AM14: 0.77083333 | AN14: 257 | AO14: 0.77083333 | AP14: 175 | AQ14: 0.77083333 | AR14: 81 | AS14: 0.77083333
A15: 6 | B15: 374 | C15: 0.77083333 | H15: 20 | I15: 0.77083333 | J15: 18.6 | K15: 0.77083333 | N15: 201 | O15: 0.77083333 | P15: 559 | Q15: 0.77083333 | R15: 170 | S15: 0.77083333 | T15: 150 | U15: 0.8125 | V15: 236 | W15: 0.77083333 | X15: 48 | Y15: 0.45833333 | Z15: 65 | AA15: 0.8125 | AB15: 191 | AC15: 0.8125 | AD15: 35 | AE15: 0.25 | AF15: 128 | AG15: 0.77083333 | AH15: 31 | AI15: 0.8125 | AJ15: 36 | AK15: 0.375 | AL15: 85 | AM15: 0.77083333 | AN15: 238 | AO15: 0.77083333 | AP15: 168 | AQ15: 0.77083333 | AR15: 69 | AS15: 0.77083333
A16: 7 | B16: 325 | C16: 0.77083333 | H16: 21 | I16: 0.33333333 | J16: 25.4 | K16: 0.77083333 | N16: 194 | O16: 0.77083333 | P16: 542 | Q16: 0.77083333 | R16: 167 | S16: 0.77083333 | T16: 134 | U16: 0.79166667 | V16: 224 | W16: 0.77083333 | X16: 39 | Y16: 0.41666667 | Z16: 65 | AA16: 0.66666667 | AB16: 187 | AC16: 0.66666667 | AD16: 35 | AE16: 0.33333333 | AF16: 125 | AG16: 0.77083333 | AH16: 29 | AI16: 0.79166667 | AJ16: 45 | AK16: 0.375 | AL16: 76 | AM16: 0.77083333 | AN16: 211 | AO16: 0.77083333 | AP16: 165 | AQ16: 0.77083333 | AR16: 49 | AS16: 0.79166667
A17: 8 | B17: 435 | C17: 0.77083333 | H17: 105 | I17: 0.75 | J17: 24.9 | K17: 0.66666667 | N17: 201 | O17: 0.77083333 | P17: 560 | Q17: 0.77083333 | R17: 166 | S17: 0.77083333 | T17: 146 | U17: 0.77083333 | V17: 231 | W17: 0.77083333 | X17: 38 | Y17: 0.45833333 | Z17: 64 | AA17: 0.5 | AB17: 178 | AC17: 0.5 | AD17: 26 | AE17: 0.25 | AF17: 106 | AG17: 0.5 | AH17: 29 | AI17: 0.77083333 | AJ17: 43 | AK17: 0.41666667 | AL17: 87 | AM17: 0.77083333 | AN17: 249 | AO17: 0.77083333 | AP17: 178 | AQ17: 0.75 | AR17: 73 | AS17: 0.77083333
A18: 9 | B18: 380 | C18: 0.79166667 | H18: 55 | I18: 0.20833333 | J18: 22.9 | K18: 0.45833333 | N18: 214 | O18: 0.77083333 | P18: 589 | Q18: 0.77083333 | R18: 178 | S18: 0.79166667 | T18: 159 | U18: 0.77083333 | V18: 255 | W18: 0.77083333 | X18: 38 | Y18: 0.41666667 | Z18: 54 | AA18: 0.66666667 | AB18: 154 | AC18: 0.66666667 | AD18: 29 | AE18: 0.45833333 | AF18: 84 | AG18: 0.77083333 | AH18: 30 | AI18: 0.8125 | AJ18: 47 | AK18: 0.375 | AL18: 89 | AM18: 0.77083333 | AN18: 266 | AO18: 0.77083333 | AP18: 189 | AQ18: 0.77083333 | AR18: 71 | AS18: 0.77083333
A19: 10 | B19: 370 | C19: 0.77083333 | H19: 20 | I19: 0.77083333 | J19: 19 | K19: 0.041666667 | N19: 208 | O19: 0.77083333 | P19: 581 | Q19: 0.77083333 | R19: 175 | S19: 0.79166667 | T19: 158 | U19: 0.77083333 | V19: 253 | W19: 0.77083333 | X19: 38 | Y19: 0.45833333 | Z19: 54 | AA19: 0.5 | AB19: 154 | AC19: 0.5 | AD19: 26 | AE19: 0.125 | AF19: 110 | AG19: 0.8125 | AH19: 28 | AI19: 0.83333333 | AJ19: 47 | AK19: 0.66666667 | AL19: 86 | AM19: 0.79166667 | AN19: 246 | AO19: 0.79166667 | AP19: 177 | AQ19: 0.79166667 | AR19: 68 | AS19: 0.77083333
A20: 11 | B20: 366 | C20: 0.77083333 | H20: 21 | I20: 0.77083333 | J20: 17 | K20: 0.083333333 | N20: 202 | O20: 0.77083333 | P20: 571 | Q20: 0.77083333 | R20: 173 | S20: 0.77083333 | T20: 160 | U20: 0.79166667 | V20: 250 | W20: 0.77083333 | X20: 26 | Y20: 0.66666667 | Z20: 54 | AA20: 0.79166667 | AB20: 160 | AC20: 0.79166667 | AD20: 36 | AE20: 0.5 | AF20: 91 | AG20: 0.79166667 | AH20: 26 | AI20: 0.77083333 | AJ20: 28 | AK20: 0.5 | AL20: 86 | AM20: 0.77083333 | AN20: 260 | AO20: 0.77083333 | AP20: 189 | AQ20: 0.77083333 | AR20: 71 | AS20: 0.77083333
A21: 12 | B21: 362 | C21: 0.79166667 | H21: 22 | I21: 0.77083333 | J21: 17.3 | K21: 0.75 | N21: 193 | O21: 0.77083333 | P21: 526 | Q21: 0.77083333 | R21: 162 | S21: 0.79166667 | T21: 143 | U21: 0.875 | V21: 225 | W21: 0.77083333 | X21: 36 | Y21: 0.45833333 | Z21: 56 | AA21: 0.45833333 | AB21: 157 | AC21: 0.45833333 | AD21: 37 | AE21: 0.25 | AF21: 82 | AG21: 0.77083333 | AH21: 24 | AI21: 0.79166667 | AJ21: 43 | AK21: 0.375 | AL21: 89 | AM21: 0.77083333 | AN21: 245 | AO21: 0.77083333 | AP21: 176 | AQ21: 0.77083333 | AR21: 67 | AS21: 0.77083333
... A25: 16 | B25: 280 | C25: 0.77083333 | H25: 18 | I25: 0.77083333 | J25: 21.2 | K25: 0.70833333 | N25: 159 | O25: 0.75 | P25: 428 | Q25: 0.77083333 | R25: 117 | S25: 0.79166667 | T25: 118 | U25: 0.77083333 | V25: 183 | W25: 0.77083333 | X25: 18 | Y25: 0.29166667 | Z25: 48 | AA25: 0.79166667 | AB25: 130 | AC25: 0.79166667 | AD25: 39 | AE25: 0.79166667 | AF25: 72 | AG25: 0.8125 | AH25: 17 | AI25: 0.83333333 | AJ25: 6 | AK25: 0.375 | AL25: 61 | AM25: 0.79166667 | AN25: 171 | AO25: 0.79166667 | AP25: 113 | AQ25: 0.79166667 | AR25: 60 | AS25: 0.77083333
A26: 17 | B26: 259 | C26: 0.8125 | H26: 22 | I26: 0.75 | J26: 18.7 | K26: 0.41666667 | N26: - | O26: - | P26: - | Q26: - | R26: - | S26: - | T26: - | U26: - | V26: 185 | W26: 0.8125 | X26: - | Y26: - | Z26: 144 | AA26: 0.75 | AB26: 331 | AC26: 0.79166667 | AD26: 38 | AE26: 0.54166667 | AF26: 113 | AG26: 0.77083333 | AH26: 32 | AI26: 0.5 | AJ26: 12 | AK26: 0.66666667 | AL26: 134 | AM26: 0.91666667 | AN26: 376 | AO26: 0.91666667 | AP26: 240 | AQ26: 0.79166667 | AR26: 189 | AS26: 0.91666667
A27: 18 | B27: 262 | C27: 0.75 | H27: 16 | I27: 0.77083333 | J27: 12.1 | K27: 0.41666667 | L27: 1.3 | M27: 0.72916667 | N27: - | O27: - | P27: - | Q27: - | R27: - | S27: - | T27: - | U27: - | V27: 192 | W27: 0.75 | X27: - | Y27: - | Z27: 112 | AA27: 0.75 | AB27: 320 | AC27: 0.75 | AD27: 37 | AE27: 0.29166667 | AF27: 99 | AG27: 0.75 | AH27: 33 | AI27: 0.41666667 | AJ27: 8 | AK27: 0.29166667 | AL27: 121 | AM27: 0.75 | AN27: 345 | AO27: 0.75 | AP27: 185 | AQ27: 0.75 | AR27: 155 | AS27: 0.75
A28: 19 | B28: 246 | C28: 0.75 | H28: 69 | I28: 0.875 | L28: 1.2 | M28: 0.875 | N28: 141 | O28: 0.75 | P28: 415 | Q28: 0.79166667 | R28: 131 | S28: 0.79166667 | T28: 113 | U28: 0.75 | V28: 191 | W28: 0.66666667 | X28: 16 | Y28: 0.70833333 | Z28: 103 | AA28: 0.45833333 | AB28: 229 | AC28: 0.45833333 | AD28: 34 | AE28: 0.45833333 | AF28: 68 | AG28: 0.41666667 | AH28: 44 | AI28: 0.41666667 | AJ28: 18 | AK28: 0.8125 | AL28: 125 | AM28: 0.45833333 | AN28: 339 | AO28: 0.45833333 | AP28: 270 | AQ28: 0.375 | AR28: 131 | AS28: 0.54166667
A29: 20 | B29: 272 | C29: 0.75 | H29: 18 | I29: 0.8125 | L29: 1.7 | M29: 0.77083333 | N29: 150 | O29: 0.77083333 | P29: 466 | Q29: 0.35416667 | R29: 130 | S29: 0.75 | T29: 126 | U29: 0.77083333 | V29: 199 | W29: 0.77083333 | X29: 28 | Y29: 0.45833333 | Z29: 44 | AA29: 0.66666667 | AB29: 131 | AC29: 0.66666667 | AD29: 37 | AE29: 0.29166667 | AF29: 63 | AG29: 0.75 | AH29: 23 | AI29: 0.77083333 | AJ29: 38 | AK29: 0.375 | AL29: 63 | AM29: 0.75 | AN29: 183 | AO29: 0.75 | AP29: 131 | AQ29: 0.75 | AR29: 63 | AS29: 0.77083333
A30: 21 | B30: 325 | C30: 0.77083333 | H30: 20 | I30: 0.77083333 | L30: 1.4 | M30: 0.375 | N30: 170 | O30: 0.77083333 | P30: 515 | Q30: 0.77083333 | R30: 170 | S30: 0.77083333 | T30: 131 | U30: 0.77083333 | V30: 205 | W30: 0.77083333 | X30: 32 | Y30: 0.41666667 | Z30: 49 | AA30: 0.83333333 | AB30: 138 | AC30: 0.83333333 | AD30: 26 | AE30: 0.20833333 | AF30: 65 | AG30: 0.77083333 | AH30: 20 | AI30: 0.77083333 | AJ30: 46 | AK30: 0.375 | AL30: 73 | AM30: 0.77083333 | AN30: 205 | AO30: 0.77083333 | AP30: 143 | AQ30: 0.77083333 | AR30: 65 | AS30: 0.77083333
A31: 22 | B31: 320 | C31: 0.77083333 | H31: 20 | I31: 0.79166667 | L31: 1.3 | M31: 0.33333333 | N31: 170 | O31: 0.77083333 | P31: 512 | Q31: 0.77083333 | R31: 149 | S31: 0.75 | T31: 121 | U31: 0.75 | V31: 213 | W31: 0.77083333 | X31: 33 | Y31: 0.41666667 | Z31: 51 | AA31: 0.79166667 | AB31: 144 | AC31: 0.79166667 | AD31: 30 | AE31: 0.33333333 | AF31: 67 | AG31: 0.75 | AH31: 22 | AI31: 0.8125 | AJ31: 51 | AK31: 0.45833333 | AL31: 73 | AM31: 0.75 | AN31: 205 | AO31: 0.75 | AP31: 142 | AQ31: 0.75 | AR31: 63 | AS31: 0.77083333
A32: 23 | B32: 390 | C32: 0.77083333 | H32: 58 | I32: 0.75 | L32: 1.2 | M32: 0.77083333 | N32: 189 | O32: 0.77083333 | P32: 543 | Q32: 0.77083333 | R32: 166 | S32: 0.79166667 | T32: 149 | U32: 0.79166667 | V32: 226 | W32: 0.79166667 | X32: 40 | Y32: 0.41666667 | Z32: 53 | AA32: 0.5 | AB32: 149 | AC32: 0.5 | AD32: 26 | AE32: 0.25 | AF32: 70 | AG32: 0.75 | AH32: 24 | AI32: 0.83333333 | AJ32: 59 | AK32: 0.375 | AL32: 82 | AM32: 0.77083333 | AN32: 221 | AO32: 0.77083333 | AP32: 156 | AQ32: 0.72916667 | AR32: 68 | AS32: 0.77083333
A33: 24 | B33: 352 | C33: 0.77083333 | H33: 38 | I33: 0.41666667 | L33: 1.4 | M33: 0.95833333 | N33: 172 | O33: 0.77083333 | P33: 535 | Q33: 0.77083333 | R33: 157 | S33: 0.77083333 | T33: 139 | U33: 0.77083333 | V33: 224 | W33: 0.77083333 | X33: 39 | Y33: 0.45833333 | Z33: 54 | AA33: 0.41666667 | AB33: 162 | AC33: 0.41666667 | AD33: 33 | AE33: 0.33333333 | AF33: 71 | AG33: 0.75 | AH33: 24 | AI33: 0.77083333 | AJ33: 61 | AK33: 0.41666667 | AL33: 77 | AM33: 0.77083333 | AN33: 216 | AO33: 0.77083333 | AP33: 152 | AQ33: 0.77083333 | AR33: 67 | AS33: 0.77083333
A34: 25 | B34: 317 | C34: 0.77083333 | H34: 18 | I34: 0.75 | L34: 1.3 | M34: 0.75 | N34: 165 | O34: 0.77083333 | P34: 522 | Q34: 0.77083333 | R34: 147 | S34: 0.77083333 | T34: 141 | U34: 0.79166667 | V34: 216 | W34: 0.77083333 | X34: 24 | Y34: 0.45833333 | Z34: 48 | AA34: 0.77083333 | AB34: 141 | AC34: 0.77083333 | AD34: 36 | AE34: 0.625 | AF34: 71 | AG34: 0.77083333 | AH34: 23 | AI34: 0.83333333 | AJ34: 23 | AK34: 0.41666667 | AL34: 72 | AM34: 0.77083333 | AN34: 222 | AO34: 0.77083333 | AP34: 156 | AQ34: 0.77083333 | AR34: 67 | AS34: 0.77083333
A35: 26 | B35: 346 | C35: 0.77083333 | H35: 10 | I35: 0.041666667 | L35: 1.2 | M35: 0.54166667 | N35: 189 | O35: 0.77083333 | P35: 559 | Q35: 0.77083333 | R35: 167 | S35: 0.75 | T35: 155 | U35: 0.75 | V35: 236 | W35: 0.77083333 | X35: 25 | Y35: 0.70833333 | Z35: 65 | AA35: 0.54166667 | AB35: 183 | AC35: 0.54166667 | AD35: 36 | AE35: 0.45833333 | AF35: 69 | AG35: 0.75 | AH35: 57 | AI35: 0.41666667 | AJ35: 49 | AK35: 0.45833333 | AL35: 88 | AM35: 0.41666667 | AN35: 245 | AO35: 0.41666667 | AP35: 166 | AQ35: 0.75 | AR35: 69 | AS35: 0.75
A36: 27 | B36: 313 | C36: 0.77083333 | H36: 5 | I36: 0.75 | L36: 1.2 | M36: 0.29166667 | N36: 171 | O36: 0.77083333 | P36: 507 | Q36: 0.77083333 | R36: 151 | S36: 0.77083333 | T36: 137 | U36: 0.77083333 | V36: 210 | W36: 0.77083333 | X36: 39 | Y36: 0.41666667 | Z36: 55 | AA36: 0.79166667 | AB36: 157 | AC36: 0.79166667 | AD36: 31 | AE36: 0.79166667 | AF36: 66 | AG36: 0.77083333 | AH36: 23 | AI36: 0.8125 | AJ36: 59 | AK36: 0.58333333 | AL36: 74 | AM36: 0.77083333 | AN36: 209 | AO36: 0.77083333 | AP36: 148 | AQ36: 0.72916667 | AR36: 62 | AS36: 0.75
A37: 28 | B37: 321 | C37: 0.77083333 | H37: 20 | I37: 0.75 | L37: 1.2 | M37: 0.16666667 | N37: 170 | O37: 0.77083333 | P37: 502 | Q37: 0.77083333 | R37: 152 | S37: 0.77083333 | T37: 137 | U37: 0.77083333 | V37: 207 | W37: 0.77083333 | X37: 37 | Y37: 0.375 | Z37: 59 | AA37: 0.375 | AB37: 148 | AC37: 0.375 | AD37: 34 | AE37: 0.29166667 | AF37: 62 | AG37: 0.77083333 | AH37: 23 | AI37: 0.79166667 | AJ37: 56 | AK37: 0.375 | AL37: 75 | AM37: 0.75 | AN37: 212 | AO37: 0.75 | AP37: 150 | AQ37: 0.75 | AR37: 63 | AS37: 0.75
A38: 29 | B38: 325 | C38: 0.77083333 | H38: 21 | I38: 0.77083333 | L38: 1.2 | M38: 0.77083333 | N38: 170 | O38: 0.77083333 | P38: 504 | Q38: 0.77083333 | R38: 148 | S38: 0.77083333 | T38: 140 | U38: 0.77083333 | V38: 207 | W38: 0.77083333 | X38: 39 | Y38: 0.45833333 | Z38: 55 | AA38: 0.79166667 | AB38: 155 | AC38: 0.79166667 | AD38: 35 | AE38: 0.91666667 | AF38: 67 | AG38: 0.77083333 | AH38: 22 | AI38: 0.75 | AJ38: 52 | AK38: 0.45833333 | AL38: 75 | AM38: 0.75 | AN38: 212 | AO38: 0.75 | AP38: 151 | AQ38: 0.77083333 | AR38: 66 | AS38: 0.75
A39: 30 | B39: 354 | C39: 0.77083333 | H39: 21 | I39: 0.77083333 | L39: 1.4 | M39: 0.375 | N39: 178 | O39: 0.77083333 | P39: 523 | Q39: 0.77083333 | R39: 161 | S39: 0.75 | T39: 144 | U39: 0.77083333 | V39: 216 | W39: 0.75 | X39: 42 | Y39: 0.41666667 | Z39: 57 | AA39: 0.79166667 | AB39: 166 | AC39: 0.79166667 | AD39: 32 | AE39: 0.79166667 | AF39: 67 | AG39: 0.75 | AH39: 22 | AI39: 0.75 | AJ39: 59 | AK39: 0.58333333 | AL39: 80 | AM39: 0.75 | AN39: 231 | AO39: 0.75 | AP39: 162 | AQ39: 0.77083333 | AR39: 69 | AS39: 0.75
A40: 31 | B40: 341 | C40: 0.75 | H40: 20 | I40: 0.75 | J40: 17.6 | K40: 0.41666667 | L40: 1.3 | M40: 0.16666667 | N40: 185 | O40: 0.75 | P40: 547 | Q40: 0.75 | R40: 164 | S40: 0.75 | T40: 171 | U40: 0.72916667 | V40: 223 | W40: 0.75 | X40: 39 | Y40: 0.375 | Z40: 55 | AA40: 0.5 | AB40: 156 | AC40: 0.5 | AD40: 34 | AE40: 0.25 | AF40: 70 | AG40: 0.77083333 | AH40: 22 | AI40: 0.8125 | AJ40: 58 | AK40: 0.41666667 | AL40: 84 | AM40: 0.75 | AN40: 237 | AO40: 0.75 | AP40: 167 | AQ40: 0.75 | AR40: 72 | AS40: 0.75
A41: 32
A44: Monthly | B44: =MAX(B10:B41) -> 435 | D44: =MAX(D10:D41) -> 0 | F44: =MAX(F10:F41) -> 0 | H44: =MAX(H10:H41) -> 105 | J44: =MAX(J10:J41) -> 26.7 | L44: =MAX(L10:L41) -> 1.7 | N44: =MAX(N10:N41) -> 214 | P44: =MAX(P10:P41) -> 589 | R44: =MAX(R10:R41) -> 178 | T44: =MAX(T10:T41) -> 171 | V44: =MAX(V10:V41) -> 255 | X44: =MAX(X10:X41) -> 48 | Z44: =MAX(Z10:Z41) -> 144 | AB44: =MAX(AB10:AB41) -> 331 | AD44: =MAX(AD10:AD41) -> 39 | AF44: =MAX(AF10:AF41) -> 141 | AH44: =MAX(AH10:AH41) -> 57 | AJ44: =MAX(AJ10:AJ41) -> 61 | AL44: =MAX(AL10:AL41) -> 134 | AN44: =MAX(AN10:AN41) -> 376 | AP44: =MAX(AP10:AP41) -> 270 | AR44: =MAX(AR10:AR41) -> 189
A49: …………….. …………….. ……………..
A50: Prepared by Checked by Approved by

Sheet Kartik 
A1: NEPAL ELECTRICITY AUTHORITY
A2: DHARAN DISTRIBUTION CENTER
A4: Peak Load Details
A6: Month: | B6: Kartik | C6: 2082
A8: Day | B8: 33KV Duhabi-Dharan | F8: 33KV Dharan-Dhankuta | J8: 33KV Dharan-Chatara Bayarban | N8: 33/11KV, 16.6MVA Power Trf 1 | P8: 11KV Incomer 1 | R8: Dharan | T8: Bagarkot | V8: Local Chatara | X8: BPKIHS | Z8: 33/11KV, 8MVA Power Trf 2 | AB8: 11KV Incomer 2 | AD8: Khanepani | AF8: Railway | AH8: British | AJ8: Industrial | AL8: 33/11KV, 8MVA Power Trf 3 | AN8: 11KV Incomer 3 | AP8: Bhanu | AR8: Panmara
B9: Max. Import (A) | C9: Time | D9: Max. Export (A) | E9: Time | F9: Max. Import (A) | G9: Time | H9: Max. Export (A) | I9: Time | J9: Max. Import (A) | K9: Time | L9: Max. Export (A) | M9: Time | N9: Max. (A) | O9: Time | P9: Max. (A) | Q9: Time | R9: Max. (A) | S9: Time | T9: Max. (A) | U9: Time | V9: Max. (A) | W9: Time | X9: Max. (A) | Y9: Time | Z9: Max. (A) | AA9: Time | AB9: Max. (A) | AC9: Time | AD9: Max. (A) | AE9: Time | AF9: Max. (A) | AG9: Time | AH9: Max. (A) | AI9: Time | AJ9: Max. (A) | AK9: Time | AL9: Max. (A) | AM9: Time | AN9: Max. (A) | AO9: Time | AP9: Max. (A) | AQ9: Time | AR9: Max. (A) | AS9: Time
A10: 1 | B10: 331 | C10: 0.77083333 | H10: 56 | I10: 0.375 | J10: 18.3 | K10: 0.54166667 | N10: 180 | O10: 0.77083333 | P10: 542 | Q10: 0.77083333 | R10: 169 | S10: 0.77083333 | T10: 149 | U10: 0.77083333 | V10: 236 | W10: 0.77083333 | X10: 23 | Y10: 0.33333333 | Z10: 48 | AA10: 0.77083333 | AB10: 142 | AC10: 0.77083333 | AD10: 34 | AE10: 0.625 | AF10: 73 | AG10: 0.77083333 | AH10: 22 | AI10: 0.79166667 | AJ10: 25 | AK10: 0.45833333 | AL10: 81 | AM10: 0.77083333 | AN10: 241 | AO10: 0.77083333 | AP10: 184 | AQ10: 0.79166667 | AR10: 65 | AS10: 0.77083333
A11: 2 | B11: 346 | C11: 0.77083333 | H11: 25 | I11: 0.77083333 | J11: 16.1 | K11: 0.33333333 | N11: 196 | O11: 0.77083333 | P11: 549 | Q11: 0.77083333 | R11: 167 | S11: 0.77083333 | T11: 152 | U11: 0.77083333 | V11: 227 | W11: 0.77083333 | X11: 41 | Y11: 0.375 | Z11: 52 | AA11: 0.77083333 | AB11: 138 | AC11: 0.77083333 | AD11: 35 | AE11: 0.29166667 | AF11: 69 | AG11: 0.77083333 | AH11: 19 | AI11: 0.8125 | AJ11: 43 | AK11: 0.375 | AL11: 88 | AM11: 0.75 | AN11: 226 | AO11: 0.75 | AP11: 163 | AQ11: 0.75 | AR11: 62 | AS11: 0.75
A12: 3 | B12: 343 | C12: 0.79166667 | H12: 22 | I12: 0.79166667 | J12: 14.6 | K12: 0.16666667 | N12: 197 | O12: 0.77083333 | P12: 581 | Q12: 0.77083333 | R12: 174 | S12: 0.75 | T12: 164 | U12: 0.75 | V12: 244 | W12: 0.77083333 | X12: 22 | Y12: 0.41666667 | Z12: 54 | AA12: 0.75 | AB12: 143 | AC12: 0.75 | AD12: 32 | AE12: 0.5 | AF12: 69 | AG12: 0.77083333 | AH12: 19 | AI12: 0.75 | AJ12: 11 | AK12: 0.58333333 | AL12: 86 | AM12: 0.77083333 | AN12: 234 | AO12: 0.77083333 | AP12: 171 | AQ12: 0.77083333 | AR12: 66 | AS12: 0.77083333
A13: 4 | B13: 319 | C13: 0.77083333 | H13: 20 | I13: 0.77083333 | J13: 17.8 | K13: 0.625 | N13: 192 | O13: 0.75 | P13: 562 | Q13: 0.75 | R13: 169 | S13: 0.75 | T13: 157 | U13: 0.77083333 | V13: 239 | W13: 0.77083333 | X13: 22 | Y13: 0.375 | Z13: 52 | AA13: 0.77083333 | AB13: 147 | AC13: 0.77083333 | AD13: 35 | AE13: 0.29166667 | AF13: 76 | AG13: 0.75 | AH13: 19 | AI13: 0.79166667 | AJ13: 8 | AK13: 0.77083333 | AL13: 78 | AM13: 0.75 | AN13: 218 | AO13: 0.75 | AP13: 158 | AQ13: 0.75 | AR13: 67 | AS13: 0.75
A14: 5 | B14: 320 | C14: 0.75 | H14: 20 | I14: 0.77083333 | J14: 15 | K14: 0.75 | N14: 184 | O14: 0.75 | P14: 540 | Q14: 0.75 | R14: 158 | S14: 0.75 | T14: 146 | U14: 0.75 | V14: 229 | W14: 0.75 | X14: 21 | Y14: 0.33333333 | Z14: 49 | AA14: 0.77083333 | AB14: 141 | AC14: 0.77083333 | AD14: 31 | AE14: 0.72916667 | AF14: 71 | AG14: 0.75 | AH14: 19 | AI14: 0.77083333 | AJ14: 10 | AK14: 0.45833333 | AL14: 75 | AM14: 0.75 | AN14: 210 | AO14: 0.75 | AP14: 151 | AQ14: 0.77083333 | AR14: 65 | AS14: 0.75
A15: 6 | B15: 300 | C15: 0.77083333 | H15: 19 | I15: 0.77083333 | J15: 13.7 | K15: 0.75 | N15: 179 | O15: 0.75 | P15: 516 | Q15: 0.75 | R15: 142 | S15: 0.75 | T15: 148 | U15: 0.75 | V15: 212 | W15: 0.79166667 | X15: 21 | Y15: 0.41666667 | Z15: 34 | AA15: 0.77083333 | AB15: 102 | AC15: 0.77083333 | AD15: 34 | AE15: 0.29166667 | AF15: 70 | AG15: 0.77083333 | AH15: 18 | AI15: 0.75 | AJ15: 5 | AK15: 0.041666667 | AL15: 68 | AM15: 0.75 | AN15: 185 | AO15: 0.75 | AP15: 121 | AQ15: 0.77083333 | AR15: 64 | AS15: 0.77083333
A16: 7 | B16: 305 | C16: 0.75 | H16: 20 | I16: 0.75 | J16: 15.4 | K16: 0.58333333 | N16: 171 | O16: 0.75 | P16: 505 | Q16: 0.75 | R16: 147 | S16: 0.75 | T16: 144 | U16: 0.75 | V16: 214 | W16: 0.75 | X16: 33 | Y16: 0.41666667 | Z16: 48 | AA16: 0.77083333 | AB16: 130 | AC16: 0.77083333 | AD16: 38 | AE16: 0.66666667 | AF16: 70 | AG16: 0.75 | AH16: 19 | AI16: 0.79166667 | AJ16: 7 | AK16: 0.25 | AL16: 70 | AM16: 0.77083333 | AN16: 196 | AO16: 0.75 | AP16: 134 | AQ16: 0.77083333 | AR16: 63 | AS16: 0.75
A17: 8 | B17: 324 | C17: 0.75 | H17: 24 | I17: 0.75 | J17: 7.9 | K17: 0.125 | L17: 1.2 | M17: 0.75 | N17: 173 | O17: 0.75 | P17: 511 | Q17: 0.75 | R17: 149 | S17: 0.75 | T17: 143 | U17: 0.77083333 | V17: 216 | W17: 0.75 | X17: 21 | Y17: 0.375 | Z17: 43 | AA17: 0.58333333 | AB17: 122 | AC17: 0.58333333 | AD17: 39 | AE17: 0.625 | AF17: 69 | AG17: 0.77083333 | AH17: 18 | AI17: 0.8125 | AJ17: 8 | AK17: 0.41666667 | AL17: 73 | AM17: 0.75 | AN17: 204 | AO17: 0.75 | AP17: 141 | AQ17: 0.75 | AR17: 62 | AS17: 0.75
A18: 9 | B18: 331 | C18: 0.75 | H18: 24 | I18: 0.75 | L18: 1.1 | M18: 0.72916667 | N18: 189 | O18: 0.77083333 | P18: 536 | Q18: 0.77083333 | R18: 160 | S18: 0.77083333 | T18: 146 | U18: 0.77083333 | V18: 219 | W18: 0.77083333 | X18: 36 | Y18: 0.375 | Z18: 50 | AA18: 0.66666667 | AB18: 139 | AC18: 0.66666667 | AD18: 38 | AE18: 0.20833333 | AF18: 66 | AG18: 0.75 | AH18: 19 | AI18: 0.79166667 | AJ18: 38 | AK18: 0.66666667 | AL18: 77 | AM18: 0.77083333 | AN18: 216 | AO18: 0.77083333 | AP18: 156 | AQ18: 0.77083333 | AR18: 62 | AS18: 0.75
A19: 10 | B19: 306 | C19: 0.75 | H19: 20 | I19: 0.75 | L19: 1.1 | M19: 0.75 | N19: 162 | O19: 0.77083333 | P19: 494 | Q19: 0.77083333 | R19: 150 | S19: 0.77083333 | T19: 136 | U19: 0.77083333 | V19: 208 | W19: 0.77083333 | X19: 31 | Y19: 0.5 | Z19: 50 | AA19: 0.45833333 | AB19: 150 | AC19: 0.45833333 | AD19: 38 | AE19: 0.25 | AF19: 65 | AG19: 0.75 | AH19: 18 | AI19: 0.83333333 | AJ19: 41 | AK19: 0.5 | AL19: 69 | AM19: 0.75 | AN19: 197 | AO19: 0.75 | AP19: 137 | AQ19: 0.75 | AR19: 58 | AS19: 0.75
A20: 11 | B20: 308 | C20: 0.75 | H20: 20 | I20: 0.75 | J20: 13.3 | K20: 0.66666667 | L20: 1 | M20: 0.083333333 | N20: 173 | O20: 0.75 | P20: 506 | Q20: 0.75 | R20: 153 | S20: 0.75 | T20: 139 | U20: 0.75 | V20: 209 | W20: 0.75 | X20: 37 | Y20: 0.375 | Z20: 53 | AA20: 0.33333333 | AB20: 139 | AC20: 0.33333333 | AD20: 39 | AE20: 0.25 | AF20: 59 | AG20: 0.75 | AH20: 22 | AI20: 0.79166667 | AJ20: 37 | AK20: 0.41666667 | AL20: 74 | AM20: 0.75 | AN20: 208 | AO20: 0.75 | AP20: 146 | AQ20: 0.75 | AR20: 60 | AS20: 0.75
A21: 12 | B21: 295 | C21: 0.75 | H21: 21 | I21: 0.75 | J21: 12 | K21: 0.75 | L21: 1 | M21: 0.041666667 | N21: 161 | O21: 0.75 | P21: 472 | Q21: 0.75 | R21: 143 | S21: 0.75 | T21: 132 | U21: 0.75 | V21: 194 | W21: 0.75 | X21: 38 | Y21: 0.41666667 | Z21: 49 | AA21: 0.33333333 | AB21: 143 | AC21: 0.33333333 | AD21: 38 | AE21: 0.33333333 | AF21: 61 | AG21: 0.75 | AH21: 22 | AI21: 0.8125 | AJ21: 44 | AK21: 0.41666667 | AL21: 70 | AM21: 0.75 | AN21: 197 | AO21: 0.75 | AP21: 141 | AQ21: 0.72916667 | AR21: 54 | AS21: 0.75
A22: 13 | B22: 368 | C22: 0.75 | H22: 75 | I22: 0.75 | J22: 10.9 | K22: 0.75 | N22: 155 | O22: 0.75 | P22: 461 | Q22: 0.75 | R22: 133 | S22: 0.75 | T22: 126 | U22: 0.75 | V22: 192 | W22: 0.75 | X22: 34 | Y22: 0.41666667 | Z22: 51 | AA22: 0.72916667 | AB22: 144 | AC22: 0.72916667 | AD22: 38 | AE22: 0.29166667 | AF22: 56 | AG22: 0.75 | AH22: 20 | AI22: 0.75 | AJ22: 36 | AK22: 0.375 | AL22: 65 | AM22: 0.75 | AN22: 184 | AO22: 0.75 | AP22: 130 | AQ22: 0.75 | AR22: 53 | AS22: 0.75
A23: 14 | B23: 352 | C23: 0.75 | H23: 90 | I23: 0.75 | J23: 11 | K23: 0.16666667 | L23: 1.1 | M23: 0.75 | N23: 145 | O23: 0.75 | P23: 431 | Q23: 0.75 | R23: 130 | S23: 0.75 | T23: 118 | U23: 0.75 | V23: 180 | W23: 0.75 | X23: 29 | Y23: 0.54166667 | Z23: 48 | AA23: 0.72916667 | AB23: 133 | AC23: 0.72916667 | AD23: 35 | AE23: 0.70833333 | AF23: 59 | AG23: 0.75 | AH23: 19 | AI23: 0.77083333 | AJ23: 36 | AK23: 0.54166667 | AL23: 61 | AM23: 0.75 | AN23: 173 | AO23: 0.75 | AP23: 122 | AQ23: 0.72916667 | AR23: 51 | AS23: 0.75
A24: 15 | B24: 344 | C24: 0.75 | H24: 82 | I24: 0.75 | L24: 1 | M24: 0.29166667 | N24: 143 | O24: 0.75 | P24: 431 | Q24: 0.75 | R24: 129 | S24: 0.72916667 | T24: 116 | U24: 0.72916667 | V24: 176 | W24: 0.77083333 | X24: 17 | Y24: 0.45833333 | Z24: 45 | AA24: 0.75 | AB24: 131 | AC24: 0.75 | AD24: 35 | AE24: 0.29166667 | AF24: 62 | AG24: 0.72916667 | AH24: 20 | AI24: 0.83333333 | AJ24: 12 | AK24: 0.75 | AL24: 59 | AM24: 0.75 | AN24: 179 | AO24: 0.75 | AP24: 119 | AQ24: 0.72916667 | AR24: 56 | AS24: 0.75
A25: 16 | B25: 369 | C25: 0.77083333 | H25: 88 | I25: 0.77083333 | L25: 1.3 | M25: 0.77083333 | N25: 169 | O25: 0.75 | P25: 468 | Q25: 0.77083333 | R25: 141 | S25: 0.75 | T25: 125 | U25: 0.75 | V25: 189 | W25: 0.77083333 | X25: 27 | Y25: 0.5 | Z25: 50 | AA25: 0.33333333 | AB25: 139 | AC25: 0.33333333 | AD25: 36 | AE25: 0.29166667 | AF25: 63 | AG25: 0.77083333 | AH25: 21 | AI25: 0.79166667 | AJ25: 48 | AK25: 0.625 | AL25: 75 | AM25: 0.72916667 | AN25: 214 | AO25: 0.72916667 | AP25: 156 | AQ25: 0.72916667 | AR25: 56 | AS25: 0.72916667
